Workbook

Sheet Report
P1: .
B2: QUARTERLY FINANCIAL REPORT.
B4: 1. REPORT DATA | J4: 2. EXECUTIVE SUMMARY
B6: Company: | D6: TechNova Inc. | K6: In Q4 2025, TechNova Inc. achieved revenue of $1,250,000, representing a 25% increase from the previous quarter. Gross profit margin improved to 65% due to optimized costs. Operating expenses rose moderately due to marketing investments, but net profit reached $180,000 (up 20%). Cash position remains strong at $650,000. Key risks include market competition; opportunities lie in new product launches.
B8: Period: | D8: Q4 2025 (October – December 2025)
B10: Date Prepared: | D10: 46015
B12: Prepared By: | D12: Chief Financial Officer
B14: 3. INCOME STATEMENT | J14: 4. BALANCE SHEET
D15: Current Quarter | E15: Previous Quarter | G15: Change (%) | H15: Same Quarter Last Year | M15: Current Quarter | N15: Previous Quarter
B16: Item | J16: Assets
B17: Revenue | D17: =SUM(D18:D19) -> 1250000 | E17: =SUM(E18:E19) -> 1000000 | G17: =(D17-E17)/E17 -> 0.25 | H17: 900000 | J17: Current Assets | M17: =SUM(M18:M20) -> 1200000 | N17: =SUM(N18:N20) -> 1000000
C18: Sales of goods/services | D18: 1200000 | E18: 950000 | L18: Cash and equivalents | M18: 650000 | N18: 500000
C19: Other income | D19: 50000 | E19: 50000 | L19: Accounts receivable | M19: 400000 | N19: 350000
B20: Cost of Goods Sold (COGS) | D20: 437500 | E20: 400000 | L20: Inventory | M20: 150000 | N20: 150000
B21: Gross Profit | D21: =D17-D20 -> 812500 | E21: =E17-E20 -> 600000 | G21: =(D21-E21)/E21 -> 0.35416667 | J21: Non-Current Assets | M21: =SUM(M22:M23) -> 800000 | N21: =SUM(N22:N23) -> 750000
B22: Operating Expenses | D22: =SUM(D23:D27) -> 550000 | E22: =SUM(E23:E27) -> 450000 | G22: =(D22-E22)/E22 -> 0.22222222 | L22: Property, plant & equipment | M22: 700000 | N22: 700000
C23: Salaries | D23: 300000 | E23: 250000 | L23: Intangible assets | M23: 100000 | N23: 50000
C24: Rent/Utilities | D24: 50000 | E24: 50000 | J24: Total Assets | M24: =SUM(M17,M21) -> 2000000 | N24: =SUM(N17,N21) -> 1750000
C25: Marketing | D25: 120000 | E25: 100000 | J25: Liabilities & Equity
C26: Administrative | D26: 60000 | E26: 40000 | J26: Current Liabilities | M26: =SUM(M27:M28) -> 500000 | N26: =SUM(N27:N28) -> 450000
C27: Other | D27: 20000 | E27: 10000 | L27: Accounts payable | M27: 300000 | N27: 280000
B28: Operating Profit (EBIT) | D28: =D21-D22 -> 262500 | E28: =E21-E22 -> 150000 | G28: =(D28-E28)/E28 -> 0.75 | L28: Short-term loans | M28: 200000 | N28: 170000
B29: Other Income/Expenses | D29: =SUM(D30) -> -20000 | E29: =SUM(E30) -> -15000 | G29: =(D29-E29)/E29 -> 0.33333333 | J29: Long-Term Liabilities | M29: 300000 | N29: 300000
C30: Interest on loans | D30: -20000 | E30: -15000 | J30: Equity | M30: =SUM(M31:M32) -> 1200000 | N30: =SUM(N31:N32) -> 1000000
B31: Profit Before Tax (EBT) | D31: =D28+D29 -> 242500 | E31: =E28+E29 -> 135000 | G31: =(D31-E31)/E31 -> 0.7962963 | L31: Share capital | M31: 500000 | N31: 500000
B32: Taxes | D32: 62500 | E32: 35000 | L32: Retained earnings | M32: 700000 | N32: 500000
B33: Net Profit | D33: =D31-D32 -> 180000 | E33: =E31-E32 -> 100000 | G33: =(D33-E33)/E33 -> 0.8 | H33: 80000 | J33: Total Liabilities & Equity | M33: =M26+M29+M30 -> 2000000 | N33: =N26+N29+N30 -> 1750000
B35: 5. CASH FLOW STATEMENT | F35: 6. KEY FINANCIAL RATIOS
B37: Category | D37: Current Quarter | F37: Gross Margin: | H37: =D21/D17 -> 0.65 | L37: Net Margin: | M37: =D33/D17 -> 0.144
B38: Operating Activities | F38: Operating Margin: | H38: =D28/D17 -> 0.21 | L38: Current Ratio: | M38: =M17/M26 -> 2.4
C39: Net profit | D39: 180000
C40: Depreciation | D40: 50000 | F40: 7. ANALYSIS AND COMMENTARY
C41: Changes in working capital | D41: -50000
B42: Net Cash from Operations | D42: =SUM(D39:D41) -> 180000 | G42: Revenue growth driven by successful product launch. Expenses controlled effectively, though marketing spend increased for Q1 pipeline. Compared to budget, revenue exceeded by 10%. Risks: Rising interest rates. Opportunities: Expansion into new markets.
B43: Investing Activities
C44: Purchase/sale of assets | D44: -100000
B45: Financing Activities
C46: Loans/repayments | D46: 30000 | F46: 8. RECOMMENDATIONS AND FORECAST
C47: Dividends | D47: $
B48: Net Change in Cash | D48: =SUM(D42,D44,D46:D47) -> 110000 | G48: Reduce non-essential admin costs by 10%. Forecast Q1 2026 revenue: $1,400,000 (+12%). Invest in R&D for sustained growth.
...

Sheet Sheet2
A1: =Report!L18 -> Cash and equivalents | B1: =Report!M18 -> 650000
A2: =Report!L19 -> Accounts receivable | B2: =Report!M19 -> 400000
A3: =Report!L20 -> Inventory | B3: =Report!M20 -> 150000
A4: =Report!L22 -> Property, plant & equipment | B4: =Report!M22 -> 700000
A5: =Report!L23 -> Intangible assets | B5: =Report!M23 -> 100000
A8: =Report!F37 -> Gross Margin: | B8: =Report!H37 -> 0.65 | D8: =Report!I37 -> 0 | E8: =Report!J37 -> 0 | F8: =Report!K37 -> 0
A9: =Report!F38 -> Operating Margin: | B9: =Report!H38 -> 0.21 | D9: =Report!I38 -> 0 | E9: =Report!J38 -> 0 | F9: =Report!K38 -> 0
A10: =Report!L37 -> Net Margin: | B10: =Report!M37 -> 0.144
A13: =Report!C39 -> Net profit | B13: =Report!D39 -> 180000
A14: =Report!C40 -> Depreciation | B14: =Report!D40 -> 50000
A15: =Report!C41 -> Changes in working capital | B15: =Report!D41 -> -50000
A16: =Report!C44 -> Purchase/sale of assets | B16: =Report!D44 -> -100000
A17: =Report!C46 -> Loans/repayments | B17: =Report!D46 -> 30000
A18: =Report!C47 -> Dividends | B18: =Report!D47 -> $
